Workbook
Name Slicer_City: #N/A
Name Slicer_Months__Date: #N/A
Name Slicer_Salesman: #N/A

Sheet sales_raw
A1: Date | B1: Invoice | C1: Product | D1: Customer | E1: City | F1: Salesman | G1: Qty | H1: Price | I1: Total
A2: 45751 | B2: INV00106 | C2: Semen Mortar | D2: Toko Bangunan 39 | E2: Bogor | F2: Andi | G2: 10 | H2: 55000 | I2: 550000
A3: 45707 | B3: INV00277 | C3: Bata Ringan 10cm | D3: Toko Bangunan 27 | E3: Depok | F3: Rina | G3: 10 | H3: 75000 | I3: 750000
A4: 45837 | B4: INV00407 | C4: Panel Dinding | D4: Toko Bangunan 11 | E4: Depok | F4: Budi | G4: 10 | H4: 120000 | I4: 1200000
A5: 45779 | B5: INV00598 | C5: Bata Ringan 7.5cm | D5: Toko Bangunan 1 | E5: Semarang | F5: Agus | G5: 10 | H5: 65000 | I5: 650000
A6: 45765 | B6: INV01051 | C6: Bata Ringan 7.5cm | D6: Toko Bangunan 8 | E6: Surabaya | F6: Rina | G6: 10 | H6: 65000 | I6: 650000
A7: 46003 | B7: INV01156 | C7: Bata Ringan 7.5cm | D7: Toko Bangunan 12 | E7: Jakarta | F7: Budi | G7: 10 | H7: 65000 | I7: 650000
A8: 45991 | B8: INV00075 | C8: Bata Ringan 7.5cm | D8: Toko Bangunan 8 | E8: Surabaya | F8: Andi | G8: 11 | H8: 65000 | I8: 715000
A9: 45749 | B9: INV00313 | C9: Panel Dinding | D9: Toko Bangunan 21 | E9: Tangerang | F9: Budi | G9: 11 | H9: 120000 | I9: 1320000
A10: 45827 | B10: INV00531 | C10: Semen Mortar | D10: Toko Bangunan 22 | E10: Bekasi | F10: Agus | G10: 11 | H10: 55000 | I10: 605000
A11: 45764 | B11: INV00823 | C11: Panel Dinding | D11: Toko Bangunan 44 | E11: Semarang | F11: Andi | G11: 11 | H11: 120000 | I11: 1320000
A12: 45871 | B12: INV00923 | C12: Bata Ringan 10cm | D12: Toko Bangunan 39 | E12: Bogor | F12: Budi | G12: 11 | H12: 75000 | I12: 825000
A13: 45942 | B13: INV00082 | C13: Panel Dinding | D13: Toko Bangunan 14 | E13: Bekasi | F13: Rina | G13: 12 | H13: 120000 | I13: 1440000
... A1201: 45833 | B1201: INV00820 | C1201: Bata Ringan 7.5cm | D1201: Toko Bangunan 44 | E1201: Semarang | F1201: Rina | G1201: 200 | H1201: 65000 | I1201: 13000000

Sheet targets
A1: Month | B1: Salesman | C1: Target
A2: Jan | B2: Andi | C2: 489501094
A3: Jan | B3: Budi | C3: 586356936
A4: Jan | B4: Rina | C4: 433178231
A5: Jan | B5: Sari | C5: 362208760
A6: Jan | B6: Agus | C6: 441380318
A7: Feb | B7: Andi | C7: 555148440
A8: Feb | B8: Budi | C8: 391540199
A9: Feb | B9: Rina | C9: 573696549
A10: Feb | B10: Sari | C10: 313079705
A11: Feb | B11: Agus | C11: 369802602
A12: Mar | B12: Andi | C12: 456941698
A13: Mar | B13: Budi | C13: 317407707
... A61: Dec | B61: Agus | C61: 492394117

Sheet products
A1: ProductID | B1: ProductName | C1: Category | D1: Price
A2: P001 | B2: Bata Ringan 7.5cm | C2: Material | D2: 65000
A3: P002 | B3: Bata Ringan 10cm | C3: Material | D3: 75000
A4: P003 | B4: Semen Mortar | C4: Material | D4: 55000
A5: P004 | B5: Panel Dinding | C5: Material | D5: 120000

Sheet customers
A1: CustomerID | B1: CustomerName | C1: City | D1: Segment
A2: C001 | B2: Toko Bangunan 1 | C2: Semarang | D2: Retail
A3: C002 | B3: Toko Bangunan 2 | C3: Surabaya | D3: Project
A4: C003 | B4: Toko Bangunan 3 | C4: Jakarta | D4: Distributor
A5: C004 | B5: Toko Bangunan 4 | C5: Surabaya | D5: Distributor
A6: C005 | B6: Toko Bangunan 5 | C6: Semarang | D6: Project
A7: C006 | B7: Toko Bangunan 6 | C7: Bogor | D7: Retail
A8: C007 | B8: Toko Bangunan 7 | C8: Bandung | D8: Distributor
A9: C008 | B9: Toko Bangunan 8 | C9: Surabaya | D9: Distributor
A10: C009 | B10: Toko Bangunan 9 | C10: Depok | D10: Project
A11: C010 | B11: Toko Bangunan 10 | C11: Bandung | D11: Project
A12: C011 | B12: Toko Bangunan 11 | C12: Depok | D12: Retail
... A51: C050 | B51: Toko Bangunan 50 | C51: Semarang | D51: Retail

Sheet Data Olahan
A3: Row Labels | B3: Sum of Total
A4: 2025 | B4: 2062770000
A5: Jan | B5: 194220000
A6: Feb | B6: 128775000
A7: Mar | B7: 101630000
A8: Apr | B8: 178305000
A9: May | B9: 267675000
A10: Jun | B10: 206910000
A11: Jul | B11: 191425000
A12: Aug | B12: 183880000
A13: Sep | B13: 253445000
A14: Oct | B14: 71005000
A15: Nov | B15: 172350000
... A17: Grand Total | B17: 2062770000
A24: Row Labels | B24: Sum of Total
A25: Panel Dinding | B25: 866280000
A26: Bata Ringan 10cm | B26: 411600000
A27: Bata Ringan 7.5cm | B27: 409955000
A28: Semen Mortar | B28: 374935000
A29: Grand Total | B29: 2062770000
A41: Row Labels | B41: Sum of Total
A42: Surabaya | B42: 391445000
A43: Jakarta | B43: 321625000
A44: Bogor | B44: 319885000
A45: Depok | B45: 291895000
A46: Semarang | B46: 290595000
A47: Bandung | B47: 166625000
A48: Bekasi | B48: 143095000
A49: Tangerang | B49: 137605000
A50: Grand Total | B50: 2062770000
A57: Row Labels | B57: Sum of Total
A58: Andi | B58: 2062770000
A59: Grand Total | B59: 2062770000
N76: Month | O76: (All)
A78: Salesman | B78: Years | C78: Month | D78: Actual | F78: Salesman | G78: Years | H78: Month | I78: Actual | J78: Target | K78: Achievement | L78: Status | N78: Count of Salesman | O78: Column Labels
A79: Andi | B79: 2025 | C79: Jan | D79: 194220000 | F79: Budi | G79: 2025 | H79: May | I79: 249765000 | J79: {=INDEX(targets!C:C, MATCH(1, (targets!A:A='Data Olahan'!H107)*(targets!B:B=F79), 0 ) )} -> 323811309 | K79: =IFERROR(I79/J79,0) -> 0.77132884 | L79: =IF(K79>=1,"Achieved","Not Achieved") -> Not Achieved | N79: Row Labels | O79: Not Achieved | P79: Grand Total
A80: Andi | B80: 2025 | C80: Feb | D80: 128775000 | F80: Rina | G80: 2025 | H80: Jun | I80: 266845000 | J80: {=INDEX(targets!C:C, MATCH(1, (targets!A:A='Data Olahan'!H120)*(targets!B:B=F80), 0 ) )} -> 533058667 | K80: =IFERROR(I80/J80,0) -> 0.50059218 | L80: =IF(K80>=1,"Achieved","Not Achieved") -> Not Achieved | N80: Agus | O80: 12 | P80: 12
A81: Andi | B81: 2025 | C81: Mar | D81: 101630000 | F81: Budi | G81: 2025 | H81: Sep | I81: 211555000 | J81: {=INDEX(targets!C:C, MATCH(1, (targets!A:A='Data Olahan'!H111)*(targets!B:B=F81), 0 ) )} -> 397170179 | K81: =IFERROR(I81/J81,0) -> 0.5326558 | L81: =IF(K81>=1,"Achieved","Not Achieved") -> Not Achieved | N81: Andi | O81: 12 | P81: 12
A82: Andi | B82: 2025 | C82: Apr | D82: 178305000 | F82: Andi | G82: 2025 | H82: Sep | I82: 253445000 | J82: {=INDEX(targets!C:C, MATCH(1, (targets!A:A='Data Olahan'!H99)*(targets!B:B=F82), 0 ) )} -> 489501094 | K82: =IFERROR(I82/J82,0) -> 0.51776187 | L82: =IF(K82>=1,"Achieved","Not Achieved") -> Not Achieved | N82: Budi | O82: 12 | P82: 12
A83: Andi | B83: 2025 | C83: May | D83: 267675000 | F83: Budi | G83: 2025 | H83: Oct | I83: 210025000 | J83: {=INDEX(targets!C:C, MATCH(1, (targets!A:A='Data Olahan'!H112)*(targets!B:B=F83), 0 ) )} -> 586356936 | K83: =IFERROR(I83/J83,0) -> 0.35818626 | L83: =IF(K83>=1,"Achieved","Not Achieved") -> Not Achieved | N83: Rina | O83: 12 | P83: 12
...

Sheet Data Mentah Forecast
A1: Jan | B1: 899795000 | C1: =DATE(2025, ROW(A1), 1) -> 45658
A2: Feb | B2: 764885000 | C2: =DATE(2025, ROW(A2), 1) -> 45689
A3: Mar | B3: 660070000 | C3: =DATE(2025, ROW(A3), 1) -> 45717
A4: Apr | B4: 711610000 | C4: =DATE(2025, ROW(A4), 1) -> 45748
A5: May | B5: 894380000 | C5: =DATE(2025, ROW(A5), 1) -> 45778
A6: Jun | B6: 874765000 | C6: =DATE(2025, ROW(A6), 1) -> 45809
A7: Jul | B7: 995215000 | C7: =DATE(2025, ROW(A7), 1) -> 45839
A8: Aug | B8: 742930000 | C8: =DATE(2025, ROW(A8), 1) -> 45870
A9: Sep | B9: 916915000 | C9: =DATE(2025, ROW(A9), 1) -> 45901
A10: Oct | B10: 791625000 | C10: =DATE(2025, ROW(A10), 1) -> 45931
A11: Nov | B11: 740695000 | C11: =DATE(2025, ROW(A11), 1) -> 45962
A12: Dec | B12: 809355000 | C12: =DATE(2025, ROW(A12), 1) -> 45992

Sheet Forecast 
A1: Timeline | B1: Values | C1: Forecast | D1: Lower Confidence Bound | E1: Upper Confidence Bound
A2: 45658 | B2: 899795000
A3: 45689 | B3: 764885000
A4: 45717 | B4: 660070000
A5: 45748 | B5: 711610000
A6: 45778 | B6: 894380000
A7: 45809 | B7: 874765000
A8: 45839 | B8: 995215000
A9: 45870 | B9: 742930000
A10: 45901 | B10: 916915000
A11: 45931 | B11: 791625000
A12: 45962 | B12: 740695000
A13: 45992 | B13: 809355000 | C13: 809355000 | D13: 809355000 | E13: 809355000
A14: 46023 | C14: =_xlfn.FORECAST.ETS(A14,$B$2:$B$13,$A$2:$A$13,1,1) -> 8.1905784e+08 | D14: =C14-_xlfn.FORECAST.ETS.CONFINT(A14,$B$2:$B$13,$A$2:$A$13,0.95,1,1) -> 5.9830595e+08 | E14: =C14+_xlfn.FORECAST.ETS.CONFINT(A14,$B$2:$B$13,$A$2:$A$13,0.95,1,1) -> 1.0398097e+09
A15: 46054 | C15: =_xlfn.FORECAST.ETS(A15,$B$2:$B$13,$A$2:$A$13,1,1) -> 8.2008218e+08 | D15: =C15-_xlfn.FORECAST.ETS.CONFINT(A15,$B$2:$B$13,$A$2:$A$13,0.95,1,1) -> 5.924827e+08 | E15: =C15+_xlfn.FORECAST.ETS.CONFINT(A15,$B$2:$B$13,$A$2:$A$13,0.95,1,1) -> 1.0476817e+09
A16: 46082 | C16: =_xlfn.FORECAST.ETS(A16,$B$2:$B$13,$A$2:$A$13,1,1) -> 8.2110652e+08 | D16: =C16-_xlfn.FORECAST.ETS.CONFINT(A16,$B$2:$B$13,$A$2:$A$13,0.95,1,1) -> 5.8680722e+08 | E16: =C16+_xlfn.FORECAST.ETS.CONFINT(A16,$B$2:$B$13,$A$2:$A$13,0.95,1,1) -> 1.0554058e+09
A17: 46112 | C17: =_xlfn.FORECAST.ETS(A17,$B$2:$B$13,$A$2:$A$13,1,1) -> 8.2209782e+08 | D17: =C17-_xlfn.FORECAST.ETS.CONFINT(A17,$B$2:$B$13,$A$2:$A$13,0.95,1,1) -> 5.8144291e+08 | E17: =C17+_xlfn.FORECAST.ETS.CONFINT(A17,$B$2:$B$13,$A$2:$A$13,0.95,1,1) -> 1.0627527e+09

Sheet Dashboard Performa Sales
A6: Total Sales
A7: =GETPIVOTDATA("Total",'Data Olahan'!$A$266) -> 2062770000
A16: Total Quantity
A17: =GETPIVOTDATA("Qty",'Data Olahan'!$D$266) -> 25831
A25: Total Customer
A26: =GETPIVOTDATA("[Measures].[Distinct Count of Customer]",'Data Olahan'!$A$289) -> 50
A33: Target Achievement
A34: =GETPIVOTDATA("Achievement",'Data Olahan'!$D$289) -> 0.37982741
P50: Row Labels | Q50: Average of Achievement
P51: Sari | Q51: 0.45677675
P52: Budi | Q52: 0.39727791
P53: Rina | Q53: 0.38930815
P54: Andi | Q54: 0.35685703
P55: Agus | Q55: 0.29891724
P56: Grand Total | Q56: 0.37982741
O78: Timeline | P78: Values | Q78: Forecast | R78: Lower Confidence Bound | S78: Upper Confidence Bound
O79: 45658 | P79: 899795000
O80: 45689 | P80: 764885000
O81: 45717 | P81: 660070000
O82: 45748 | P82: 711610000
O83: 45778 | P83: 894380000
O84: 45809 | P84: 874765000
O85: 45839 | P85: 995215000
O86: 45870 | P86: 742930000
O87: 45901 | P87: 916915000
O88: 45931 | P88: 791625000
O89: 45962 | P89: 740695000
O90: 45992 | P90: 809355000 | Q90: 809355000 | R90: 809355000 | S90: 809355000
O91: 46023 | Q91: 8.1905784e+08 | R91: 5.9830595e+08 | S91: 1.0398097e+09
O92: 46054 | Q92: 8.2008218e+08 | R92: 5.924827e+08 | S92: 1.0476817e+09
O93: 46082 | Q93: 8.2110652e+08 | R93: 5.8680722e+08 | S93: 1.0554058e+09
O94: 46112 | Q94: 8.2209782e+08 | R94: 5.8144291e+08 | S94: 1.0627527e+09
